Workbook
Name EnhancementHabitats2: 'Z8 TARGET ENHANCEMENT'!$K$1:$K$508

Sheet RESULTS
C3: SINGAPORE BIODIVERSITY ACCOUNTING METRIC 1.1
C4: RESULTS
C6: PROJECT NAME:
C7: PROJECT STAGE:
C8: ASSESSOR:
C9: REVIEWER:
C10: DATE OF ASSESSMENT:
C12: BASELINE | E12: TERRESTRIAL UNITS | F12: ='A1 Baseline - Terrestrial'!L256 -> 0 | G12: TOTAL
E13: FRESHWATER UNITS | F13: ='B1 Baseline - FW'!L256 -> 0
E14: MARINE UNITS | F14: ='C1 Baseline - Marine'!L256 -> 0 | G14: =SUM(F12:F14) -> 0
C15: POST DEVELOPMENT | E15: TERRESTRIAL UNITS | F15: ='A1 Baseline - Terrestrial'!P256+'A2 Creation - Terrestrial'!N255+'A3 Enhancement - Terrestrial'!W255 -> 6 | G15: TOTAL
E16: FRESHWATER UNITS | F16: ='B1 Baseline - FW'!P256+'B2 Creation - FW'!N255+'B3 Enhancement - FW'!W255 -> 0
E17: MARINE UNITS | F17: ='C1 Baseline - Marine'!P256+'C2 Creation - Marine'!N255+'C3 Enhancement - Marine'!W255 -> 0 | G17: =SUM(F15:F17) -> 6
C18: NET CHANGE - BIODIVERSITY UNITS | E18: TERRESTRIAL UNITS | F18: =F15-F12 -> 6
E19: FRESHWATER UNITS | F19: =F16-F13 -> 0
E20: MARINE UNITS | F20: =F17-F14 -> 0
C21: NET % CHANGE - BIODIVERSITY UNITS | E21: TERRESTRIAL UNITS | F21: =IFERROR(((F15-F12)/F12),"0") -> 0
E22: FRESHWATER UNITS | F22: =IFERROR(((F16-F13)/F13),"0") -> 0
E23: MARINE UNITS | F23: =IFERROR(((F17-F14)/F14),"0") -> 0
C24: NET CHANGE - COMBINED | E24: =F18+F19+F20 -> 6
C25: NET % CHANGE - COMBINED | E25: =IFERROR(((G17-G14)/G14),"COMPLETE ASSESSMENT") -> COMPLETE ASSESSMENT
C27: HABITAT TRADING SATISFIED? | E27: TO BE CONFIGURED IN FUTURE VERSION
C29: ERROR CHECK | E29: BASELINE HABITAT LOSS = HABITAT CREATED | G29: DIFFERENCE IN AREA (NET INCREASE: CREATION - LOSS) | H29: COMMENTARY
C30: TERRESTRIAL | E30: =IFERROR(IF(OR(('A2 Creation - Terrestrial'!F255-'A1 Baseline - Terrestrial'!R256)>0.01,('A2 Creation - Terrestrial'!F255-'A1 Baseline - Terrestrial'!R256)<-0.01),"N","Y"),"") -> N | G30: ='A2 Creation - Terrestrial'!F255-'A1 Baseline - Terrestrial'!R256 -> 4
C31: FRESHWATER | E31: =IFERROR(IF(OR(('B2 Creation - FW'!F255-'B1 Baseline - FW'!R256)>0.01,('B2 Creation - FW'!F255-'B1 Baseline - FW'!R256)<-0.01),"N","Y"),"") -> Y | G31: ='B2 Creation - FW'!F255-'B1 Baseline - FW'!R256 -> 0
C32: MARINE | E32: =IFERROR(IF(OR(('C2 Creation - Marine'!F255-'C1 Baseline - Marine'!R256)>0.01,('C2 Creation - Marine'!F255-'C1 Baseline - Marine'!R256)<-0.01),"N","Y"),"") -> Y | G32: ='C2 Creation - Marine'!F255-'C1 Baseline - Marine'!R256 -> 0
C33: COMBINED | E33: =IFERROR(IF(OR((G33)>0,(G33)<0),"N","Y"),"") -> N | G33: =SUM(G30:G32) -> 4

Sheet A1 Baseline - Terrestrial
X1: 1
D2: BASELINE | X2: 1
D3: TERRESTRIAL UNITS | X3: 1
X4: 1
X5: 1
E6: Habitats and Areas | G6: Distinctiveness | I6: Condition | K6: Habitat Trading (compensation requirement) | L6: Ecological Baseline | N6: Lost, Retained and Enhanced Biodiversity Units | T6: Justifications and Comments | X6: =IF(F6="",0,1) -> 0
D7: Ref | E7: Habitat Type | F7: Area (hectares) | G7: Distinctiveness | H7: Score | I7: Condition | J7: Score | L7: Total Terrestrial Units | N7: Area Retained (ha) | O7: Area Enhanced (ha) | P7: Baseline Units Retained | Q7: Baseline Units Enhanced | R7: Area Lost (ha) | S7: Terrestrial Units Lost | X7: =IF(F7="",0,1) -> 1
D8: 1 | F8: 6 | G8: =IFERROR(VLOOKUP(E8,'Z1 HAB CLASS'!$D$4:$E$45,2,FALSE)," ") | H8: =IFERROR(VLOOKUP(G8,'Z1 HAB CLASS'!$L$3:$N$9,2,FALSE)," ") | I8: Poor | J8: =IFERROR(VLOOKUP(I8,'Z3 CONDITION VALUE'!$A$3:$B$5,2,FALSE)," ") -> 1 | K8: =IFERROR(VLOOKUP(G8,'Z1 HAB CLASS'!$L$4:$N$9,3,FALSE)," ") | L8: =IFERROR(F8*H8*J8," ") | N8: 3 | O8: 2 | P8: =IFERROR(N8*H8*J8," ") | Q8: =IFERROR(O8*H8*J8, " ") | R8: =IF(E8="","",IF(F8<N8+O8, "Errors in Areas",F8-(N8+O8))) | S8: =IFERROR(R8*H8*J8," ") | X8: =IF(F8="",0,1) -> 1
D9: 2 | F9: 3 | G9: =IFERROR(VLOOKUP(E9,'Z1 HAB CLASS'!$D$4:$E$45,2,FALSE)," ") | H9: =IFERROR(VLOOKUP(G9,'Z1 HAB CLASS'!$L$3:$N$9,2,FALSE)," ") | I9: Moderate | J9: =IFERROR(VLOOKUP(I9,'Z3 CONDITION VALUE'!$A$3:$B$5,2,FALSE)," ") -> 2 | K9: =IFERROR(VLOOKUP(G9,'Z1 HAB CLASS'!$L$4:$N$9,3,FALSE)," ") | L9: =IFERROR(F9*H9*J9," ") | P9: =IFERROR(N9*H9*J9," ") | Q9: =IFERROR(O9*H9*J9, " ") | R9: =IF(E9="","",IF(F9<N9+O9, "Errors in Areas",F9-(N9+O9))) | S9: =IFERROR(R9*H9*J9," ") | X9: =IF(F9="",0,1) -> 1
D10: 3 | F10: 2 | G10: =IFERROR(VLOOKUP(E10,'Z1 HAB CLASS'!$D$4:$E$45,2,FALSE)," ") | H10: =IFERROR(VLOOKUP(G10,'Z1 HAB CLASS'!$L$3:$N$9,2,FALSE)," ") | I10: Moderate | J10: =IFERROR(VLOOKUP(I10,'Z3 CONDITION VALUE'!$A$3:$B$5,2,FALSE)," ") -> 2 | K10: =IFERROR(VLOOKUP(G10,'Z1 HAB CLASS'!$L$4:$N$9,3,FALSE)," ") | L10: =IFERROR(F10*H10*J10," ") | P10: =IFERROR(N10*H10*J10," ") | Q10: =IFERROR(O10*H10*J10, " ") | R10: =IF(E10="","",IF(F10<N10+O10, "Errors in Areas",F10-(N10+O10))) | S10: =IFERROR(R10*H10*J10," ") | X10: =IF(F10="",0,1) -> 1
D11: 4 | G11: =IFERROR(VLOOKUP(E11,'Z1 HAB CLASS'!$D$4:$E$45,2,FALSE)," ") | H11: =IFERROR(VLOOKUP(G11,'Z1 HAB CLASS'!$L$3:$N$9,2,FALSE)," ") | J11: =IFERROR(VLOOKUP(I11,'Z3 CONDITION VALUE'!$A$3:$B$5,2,FALSE)," ") | K11: =IFERROR(VLOOKUP(G11,'Z1 HAB CLASS'!$L$4:$N$9,3,FALSE)," ") | L11: =IFERROR(F11*H11*J11," ") | P11: =IFERROR(N11*H11*J11," ") | Q11: =IFERROR(O11*H11*J11, " ") | R11: =IF(E11="","",IF(F11<N11+O11, "Errors in Areas",F11-(N11+O11))) | S11: =IFERROR(R11*H11*J11," ") | X11: =IF(F11="",0,1) -> 0
D12: 5 | G12: =IFERROR(VLOOKUP(E12,'Z1 HAB CLASS'!$D$4:$E$45,2,FALSE)," ") | H12: =IFERROR(VLOOKUP(G12,'Z1 HAB CLASS'!$L$3:$N$9,2,FALSE)," ") | J12: =IFERROR(VLOOKUP(I12,'Z3 CONDITION VALUE'!$A$3:$B$5,2,FALSE)," ") | K12: =IFERROR(VLOOKUP(G12,'Z1 HAB CLASS'!$L$4:$N$9,3,FALSE)," ") | L12: =IFERROR(F12*H12*J12," ") | P12: =IFERROR(N12*H12*J12," ") | Q12: =IFERROR(O12*H12*J12, " ") | R12: =IF(E12="","",IF(F12<N12+O12, "Errors in Areas",F12-(N12+O12))) | S12: =IFERROR(R12*H12*J12," ") | X12: =IF(F12="",0,1) -> 0
D13: 6 | G13: =IFERROR(VLOOKUP(E13,'Z1 HAB CLASS'!$D$4:$E$45,2,FALSE)," ") | H13: =IFERROR(VLOOKUP(G13,'Z1 HAB CLASS'!$L$3:$N$9,2,FALSE)," ") | J13: =IFERROR(VLOOKUP(I13,'Z3 CONDITION VALUE'!$A$3:$B$5,2,FALSE)," ") | K13: =IFERROR(VLOOKUP(G13,'Z1 HAB CLASS'!$L$4:$N$9,3,FALSE)," ") | L13: =IFERROR(F13*H13*J13," ") | P13: =IFERROR(N13*H13*J13," ") | Q13: =IFERROR(O13*H13*J13, " ") | R13: =IF(E13="","",IF(F13<N13+O13, "Errors in Areas",F13-(N13+O13))) | S13: =IFERROR(R13*H13*J13," ") | X13: =IF(F13="",0,1) -> 0
D14: 7 | G14: =IFERROR(VLOOKUP(E14,'Z1 HAB CLASS'!$D$4:$E$45,2,FALSE)," ") | H14: =IFERROR(VLOOKUP(G14,'Z1 HAB CLASS'!$L$3:$N$9,2,FALSE)," ") | J14: =IFERROR(VLOOKUP(I14,'Z3 CONDITION VALUE'!$A$3:$B$5,2,FALSE)," ") | K14: =IFERROR(VLOOKUP(G14,'Z1 HAB CLASS'!$L$4:$N$9,3,FALSE)," ") | L14: =IFERROR(F14*H14*J14," ") | P14: =IFERROR(N14*H14*J14," ") | Q14: =IFERROR(O14*H14*J14, " ") | R14: =IF(E14="","",IF(F14<N14+O14, "Errors in Areas",F14-(N14+O14))) | S14: =IFERROR(R14*H14*J14," ") | X14: =IF(F14="",0,1) -> 0
D15: 8 | G15: =IFERROR(VLOOKUP(E15,'Z1 HAB CLASS'!$D$4:$E$45,2,FALSE)," ") | H15: =IFERROR(VLOOKUP(G15,'Z1 HAB CLASS'!$L$3:$N$9,2,FALSE)," ") | J15: =IFERROR(VLOOKUP(I15,'Z3 CONDITION VALUE'!$A$3:$B$5,2,FALSE)," ") | K15: =IFERROR(VLOOKUP(G15,'Z1 HAB CLASS'!$L$4:$N$9,3,FALSE)," ") | L15: =IFERROR(F15*H15*J15," ") | P15: =IFERROR(N15*H15*J15," ") | Q15: =IFERROR(O15*H15*J15, " ") | R15: =IF(E15="","",IF(F15<N15+O15, "Errors in Areas",F15-(N15+O15))) | S15: =IFERROR(R15*H15*J15," ") | X15: =IF(F15="",0,1) -> 0
D16: 9 | G16: =IFERROR(VLOOKUP(E16,'Z1 HAB CLASS'!$D$4:$E$45,2,FALSE)," ") | H16: =IFERROR(VLOOKUP(G16,'Z1 HAB CLASS'!$L$3:$N$9,2,FALSE)," ") | J16: =IFERROR(VLOOKUP(I16,'Z3 CONDITION VALUE'!$A$3:$B$5,2,FALSE)," ") | K16: =IFERROR(VLOOKUP(G16,'Z1 HAB CLASS'!$L$4:$N$9,3,FALSE)," ") | L16: =IFERROR(F16*H16*J16," ") | P16: =IFERROR(N16*H16*J16," ") | Q16: =IFERROR(O16*H16*J16, " ") | R16: =IF(E16="","",IF(F16<N16+O16, "Errors in Areas",F16-(N16+O16))) | S16: =IFERROR(R16*H16*J16," ") | X16: =IF(F16="",0,1) -> 0
D17: 10 | G17: =IFERROR(VLOOKUP(E17,'Z1 HAB CLASS'!$D$4:$E$45,2,FALSE)," ") | H17: =IFERROR(VLOOKUP(G17,'Z1 HAB CLASS'!$L$3:$N$9,2,FALSE)," ") | J17: =IFERROR(VLOOKUP(I17,'Z3 CONDITION VALUE'!$A$3:$B$5,2,FALSE)," ") | K17: =IFERROR(VLOOKUP(G17,'Z1 HAB CLASS'!$L$4:$N$9,3,FALSE)," ") | L17: =IFERROR(F17*H17*J17," ") | P17: =IFERROR(N17*H17*J17," ") | Q17: =IFERROR(O17*H17*J17, " ") | R17: =IF(E17="","",IF(F17<N17+O17, "Errors in Areas",F17-(N17+O17))) | S17: =IFERROR(R17*H17*J17," ") | X17: =IF(F17="",0,1) -> 0
D18: 11 | G18: =IFERROR(VLOOKUP(E18,'Z1 HAB CLASS'!$D$4:$E$45,2,FALSE)," ") | H18: =IFERROR(VLOOKUP(G18,'Z1 HAB CLASS'!$L$3:$N$9,2,FALSE)," ") | J18: =IFERROR(VLOOKUP(I18,'Z3 CONDITION VALUE'!$A$3:$B$5,2,FALSE)," ") | K18: =IFERROR(VLOOKUP(G18,'Z1 HAB CLASS'!$L$4:$N$9,3,FALSE)," ") | L18: =IFERROR(F18*H18*J18," ") | P18: =IFERROR(N18*H18*J18," ") | Q18: =IFERROR(O18*H18*J18, " ") | R18: =IF(E18="","",IF(F18<N18+O18, "Errors in Areas",F18-(N18+O18))) | S18: =IFERROR(R18*H18*J18," ") | X18: =IF(F18="",0,1) -> 0
D19: 12 | G19: =IFERROR(VLOOKUP(E19,'Z1 HAB CLASS'!$D$4:$E$45,2,FALSE)," ") | H19: =IFERROR(VLOOKUP(G19,'Z1 HAB CLASS'!$L$3:$N$9,2,FALSE)," ") | J19: =IFERROR(VLOOKUP(I19,'Z3 CONDITION VALUE'!$A$3:$B$5,2,FALSE)," ") | K19: =IFERROR(VLOOKUP(G19,'Z1 HAB CLASS'!$L$4:$N$9,3,FALSE)," ") | L19: =IFERROR(F19*H19*J19," ") | P19: =IFERROR(N19*H19*J19," ") | Q19: =IFERROR(O19*H19*J19, " ") | R19: =IF(E19="","",IF(F19<N19+O19, "Errors in Areas",F19-(N19+O19))) | S19: =IFERROR(R19*H19*J19," ") | X19: =IF(F19="",0,1) -> 0
D20: 13 | G20: =IFERROR(VLOOKUP(E20,'Z1 HAB CLASS'!$D$4:$E$45,2,FALSE)," ") | H20: =IFERROR(VLOOKUP(G20,'Z1 HAB CLASS'!$L$3:$N$9,2,FALSE)," ") | J20: =IFERROR(VLOOKUP(I20,'Z3 CONDITION VALUE'!$A$3:$B$5,2,FALSE)," ") | K20: =IFERROR(VLOOKUP(G20,'Z1 HAB CLASS'!$L$4:$N$9,3,FALSE)," ") | L20: =IFERROR(F20*H20*J20," ") | P20: =IFERROR(N20*H20*J20," ") | Q20: =IFERROR(O20*H20*J20, " ") | R20: =IF(E20="","",IF(F20<N20+O20, "Errors in Areas",F20-(N20+O20))) | S20: =IFERROR(R20*H20*J20," ") | X20: =IF(F20="",0,1) -> 0
D21: 14 | G21: =IFERROR(VLOOKUP(E21,'Z1 HAB CLASS'!$D$4:$E$45,2,FALSE)," ") | H21: =IFERROR(VLOOKUP(G21,'Z1 HAB CLASS'!$L$3:$N$9,2,FALSE)," ") | J21: =IFERROR(VLOOKUP(I21,'Z3 CONDITION VALUE'!$A$3:$B$5,2,FALSE)," ") | K21: =IFERROR(VLOOKUP(G21,'Z1 HAB CLASS'!$L$4:$N$9,3,FALSE)," ") | L21: =IFERROR(F21*H21*J21," ") | P21: =IFERROR(N21*H21*J21," ") | Q21: =IFERROR(O21*H21*J21, " ") | R21: =IF(E21="","",IF(F21<N21+O21, "Errors in Areas",F21-(N21+O21))) | S21: =IFERROR(R21*H21*J21," ") | X21: =IF(F21="",0,1) -> 0
D22: 15 | G22: =IFERROR(VLOOKUP(E22,'Z1 HAB CLASS'!$D$4:$E$45,2,FALSE)," ") | H22: =IFERROR(VLOOKUP(G22,'Z1 HAB CLASS'!$L$3:$N$9,2,FALSE)," ") | J22: =IFERROR(VLOOKUP(I22,'Z3 CONDITION VALUE'!$A$3:$B$5,2,FALSE)," ") | K22: =IFERROR(VLOOKUP(G22,'Z1 HAB CLASS'!$L$4:$N$9,3,FALSE)," ") | L22: =IFERROR(F22*H22*J22," ") | P22: =IFERROR(N22*H22*J22," ") | Q22: =IFERROR(O22*H22*J22, " ") | R22: =IF(E22="","",IF(F22<N22+O22, "Errors in Areas",F22-(N22+O22))) | S22: =IFERROR(R22*H22*J22," ") | X22: =IF(F22="",0,1) -> 0
... D255: 248 | G255: =IFERROR(VLOOKUP(E255,'Z1 HAB CLASS'!$D$4:$E$45,2,FALSE)," ") | H255: =IFERROR(VLOOKUP(G255,'Z1 HAB CLASS'!$L$3:$N$9,2,FALSE)," ") | J255: =IFERROR(VLOOKUP(I255,'Z3 CONDITION VALUE'!$A$3:$B$5,2,FALSE)," ") | K255: =IFERROR(VLOOKUP(G255,'Z1 HAB CLASS'!$L$4:$N$9,3,FALSE)," ") | L255: =IFERROR(F255*H255*J255," ") | P255: =IFERROR(N255*H255*J255," ") | Q255: =IFERROR(O255*H255*J255, " ") | R255: =IF(E255="","",IF(F255<N255+O255, "Errors in Areas",F255-(N255+O255))) | S255: =IFERROR(R255*H255*J255," ") | X255: =IF(F255="",0,1) -> 0
F256: =SUM(F8:F254) -> 11 | L256: =SUMIF(L8:L255,"<>#N/A") -> 0 | N256: =SUMIF(N8:N255,"<>#N/A") -> 3 | O256: =SUMIF(O8:O255,"<>#N/A") -> 2 | P256: =SUMIF(P8:P255,"<>#N/A") -> 0 | Q256: =SUMIF(Q8:Q255,"<>#N/A") -> 0 | R256: =SUMIF(R8:R255,"<>#N/A") -> 0 | S256: =SUMIF(S8:S255,"<>#N/A") -> 0 | X256: =IF(F256="",0,1) -> 1

Sheet A3 Enhancement - Terrestrial
Z1: 1
D2: POST-DEVELOPMENT | Z2: 1
D3: ENHANCEMENT - TERRESTRIAL HABITATS | Z3: 1
Z4: 1
E5: Habitats and Areas | I5: Habitat Trading (compensation requirement) | J5: Change | L5: Post-Development | Q5: Change in Habitat Summary | T5: Time to Target Condition | U5: Difficulty of Enhancement | V5: Difficulty Multiplier | W5: Terrestrial Units Delivered | X5: Comments and justification | Z5: 1
D6: Baseline Ref | E6: Baseline Habitat | F6: Distinctiveness Score | G6: Condition Score | H6: Proposed Habitat | J6: Distinctiveness | K6: Condition | L6: Area (ha) | M6: Distinctiveness | N6: Distinctiveness Score | O6: Target Condition | P6: Condition Score | Q6: Existing Condition | R6: Existing Habitat/Condition | S6: Proposed Habitat/Condition | T6: No. Years | Z6: 1
D7: ='A1 Baseline - Terrestrial'!D8 -> 1 | E7: =IF(OR('A1 Baseline - Terrestrial'!E8="",'A1 Baseline - Terrestrial'!O8=0), "",'A1 Baseline - Terrestrial'!E8) | F7: =IF(E7="", "", 'A1 Baseline - Terrestrial'!H8) | G7: =IF(E7="", "", 'A1 Baseline - Terrestrial'!J8) | H7: Abandoned land forest | I7: =IF(E7="","",'A1 Baseline - Terrestrial'!K8) | J7: =IF(OR(E7="",H7=""),"",IF(AND(E7=H7,G7>=P7),"Error - No Enhancement",IF(AND(E7=H7,G7<P7),"Acceptable",IF(F7>N7,"Trading Down - Unacceptable Change",IF(F7=N7,"Error - No Enhancement",'A1 Baseline - Terrestrial'!G8&" - "&IFERROR(VLOOKUP(H7,'Z1 HAB CLASS'!$D$4:$E$45,2,FALSE),"")))))) | K7: =IF(E7="","",IF(AND(E7=H7,G7>=P7),"Error - No Enhancement",IF(AND(E7=H7,G7<P7),'A1 Baseline - Terrestrial'!I8&" - "&'A3 Enhancement - Terrestrial'!O7,IF(F7>N7,"Trading Down - Unacceptable Change",IF(F7=N7,"Error - No Enhancement",IF(AND(E7<>H7,F7<N7),"Lower Distinctiveness Habitat"&" - "&O7,'A1 Baseline - Terrestrial'!I8&" - "&'A3 Enhancement - Terrestrial'!O7)))))) | L7: =IF(E7="","",'A1 Baseline - Terrestrial'!O8) | M7: =IFERROR(VLOOKUP(H7,'Z1 HAB CLASS'!$D$4:$E$45,2,FALSE)," ") -> Moderate | N7: =IFERROR(VLOOKUP(M7,'Z1 HAB CLASS'!$L$3:$N$9,2,FALSE)," ") -> 4 | O7: Poor | P7: =IFERROR(VLOOKUP(O7,'Z3 CONDITION VALUE'!$A$3:$B$5,2,FALSE)," ") -> 1 | Q7: =IF(OR('A1 Baseline - Terrestrial'!E8="", 'A1 Baseline - Terrestrial'!O8=0), "", 'A1 Baseline - Terrestrial'!I8&"") | R7: =_xludf.TEXTJOIN("/",TRUE,E7,Q7) -> #NAME? | S7: =_xludf.TEXTJOIN("/",TRUE,H7,O7) -> #NAME? | T7: {=IF(OR(R7="",S7=""),"",INDEX('Z8 TARGET ENH'!$F$6:$EO$145,_xludf.XMATCH(R7,'Z8 TARGET ENH'!$B$6:$B$145),_xludf.XMATCH(S7,'Z8 TARGET ENH'!$F$2:$EO$2)))} -> #NAME? | U7: =IF(E7="","",VLOOKUP(H7,'Z8 TARGET ENH'!$FH$7:$FJ$38,2,FALSE)) | V7: =IF(E7="","",VLOOKUP(H7,'Z8 TARGET ENH'!$FH$7:$FJ$38,3,FALSE)) | W7: =IF(E7="","",IF(T7="Not possible",0,IFERROR(L7*N7*P7-L7*F7*G7*U7+L7*F7*G7, "Error"))) | Z7: =IF(E7="",0,1) -> 0
D8: ='A1 Baseline - Terrestrial'!D9 -> 2 | E8: =IF(OR('A1 Baseline - Terrestrial'!E9="",'A1 Baseline - Terrestrial'!O9=0), "",'A1 Baseline - Terrestrial'!E9) | F8: =IF(E8="", "", 'A1 Baseline - Terrestrial'!H9) | G8: =IF(E8="", "", 'A1 Baseline - Terrestrial'!J9) | I8: =IF(E8="","",'A1 Baseline - Terrestrial'!K9) | J8: =IF(OR(E8="",H8=""),"",IF(AND(E8=H8,G8>=P8),"Error - No Enhancement",IF(AND(E8=H8,G8<P8),"Acceptable",IF(F8>N8,"Trading Down - Unacceptable Change",IF(F8=N8,"Error - No Enhancement",'A1 Baseline - Terrestrial'!G9&" - "&IFERROR(VLOOKUP(H8,'Z1 HAB CLASS'!$D$4:$E$45,2,FALSE),"")))))) | K8: =IF(E8="","",IF(AND(E8=H8,G8>=P8),"Error - No Enhancement",IF(AND(E8=H8,G8<P8),'A1 Baseline - Terrestrial'!I9&" - "&'A3 Enhancement - Terrestrial'!O8,IF(F8>N8,"Trading Down - Unacceptable Change",IF(F8=N8,"Error - No Enhancement",IF(AND(E8<>H8,F8<N8),"Lower Distinctiveness Habitat"&" - "&O8,'A1 Baseline - Terrestrial'!I9&" - "&'A3 Enhancement - Terrestrial'!O8)))))) | L8: =IF(E8="","",'A1 Baseline - Terrestrial'!O9) | M8: =IFERROR(VLOOKUP(H8,'Z1 HAB CLASS'!$D$4:$E$45,2,FALSE)," ") | N8: =IFERROR(VLOOKUP(M8,'Z1 HAB CLASS'!$L$3:$N$9,2,FALSE)," ") | P8: =IFERROR(VLOOKUP(O8,'Z3 CONDITION VALUE'!$A$3:$B$5,2,FALSE)," ") | Q8: =IF(OR('A1 Baseline - Terrestrial'!E9="", 'A1 Baseline - Terrestrial'!O9=0), "", 'A1 Baseline - Terrestrial'!I9&"") | R8: =_xludf.TEXTJOIN("/",TRUE,E8,Q8) -> #NAME? | S8: =_xludf.TEXTJOIN("/",TRUE,H8,O8) -> #NAME? | T8: {=IF(OR(R8="",S8=""),"",INDEX('Z8 TARGET ENH'!$F$6:$EO$145,MATCH(R8,'Z8 TARGET ENH'!$B$6:$B$145,0),MATCH(S8,'Z8 TARGET ENH'!$F$2:$EO$2,0)))} -> #NAME? | U8: =IF(E8="","",VLOOKUP(H8,'Z8 TARGET ENH'!$FH$7:$FJ$38,2,FALSE)) | V8: =IF(E8="","",VLOOKUP(H8,'Z8 TARGET ENH'!$FH$7:$FJ$38,3,FALSE)) | W8: =IF(E8="","",IF(T8="Not possible",0,IFERROR(L8*N8*P8-L8*F8*G8*U8+L8*F8*G8, "Error"))) | Z8: =IF(E8="",0,1) -> 0
D9: ='A1 Baseline - Terrestrial'!D10 -> 3 | E9: =IF(OR('A1 Baseline - Terrestrial'!E10="",'A1 Baseline - Terrestrial'!O10=0), "",'A1 Baseline - Terrestrial'!E10) | F9: =IF(E9="", "", 'A1 Baseline - Terrestrial'!H10) | G9: =IF(E9="", "", 'A1 Baseline - Terrestrial'!J10) | I9: =IF(E9="","",'A1 Baseline - Terrestrial'!K10) | J9: =IF(OR(E9="",H9=""),"",IF(AND(E9=H9,G9>=P9),"Error - No Enhancement",IF(AND(E9=H9,G9<P9),"Acceptable",IF(F9>N9,"Trading Down - Unacceptable Change",IF(F9=N9,"Error - No Enhancement",'A1 Baseline - Terrestrial'!G10&" - "&IFERROR(VLOOKUP(H9,'Z1 HAB CLASS'!$D$4:$E$45,2,FALSE),"")))))) | K9: =IF(E9="","",IF(AND(E9=H9,G9>=P9),"Error - No Enhancement",IF(AND(E9=H9,G9<P9),'A1 Baseline - Terrestrial'!I10&" - "&'A3 Enhancement - Terrestrial'!O9,IF(F9>N9,"Trading Down - Unacceptable Change",IF(F9=N9,"Error - No Enhancement",IF(AND(E9<>H9,F9<N9),"Lower Distinctiveness Habitat"&" - "&O9,'A1 Baseline - Terrestrial'!I10&" - "&'A3 Enhancement - Terrestrial'!O9)))))) | L9: =IF(E9="","",'A1 Baseline - Terrestrial'!O10) | M9: =IFERROR(VLOOKUP(H9,'Z1 HAB CLASS'!$D$4:$E$45,2,FALSE)," ") | N9: =IFERROR(VLOOKUP(M9,'Z1 HAB CLASS'!$L$3:$N$9,2,FALSE)," ") | P9: =IFERROR(VLOOKUP(O9,'Z3 CONDITION VALUE'!$A$3:$B$5,2,FALSE)," ") | Q9: =IF(OR('A1 Baseline - Terrestrial'!E10="", 'A1 Baseline - Terrestrial'!O10=0), "", 'A1 Baseline - Terrestrial'!I10&"") | R9: =_xludf.TEXTJOIN("/",TRUE,E9,Q9) -> #NAME? | S9: =_xludf.TEXTJOIN("/",TRUE,H9,O9) -> #NAME? | T9: {=IF(OR(R9="",S9=""),"",INDEX('Z8 TARGET ENH'!$F$6:$EO$145,MATCH(R9,'Z8 TARGET ENH'!$B$6:$B$145,0),MATCH(S9,'Z8 TARGET ENH'!$F$2:$EO$2,0)))} -> #NAME? | U9: =IF(E9="","",VLOOKUP(H9,'Z8 TARGET ENH'!$FH$7:$FJ$38,2,FALSE)) | V9: =IF(E9="","",VLOOKUP(H9,'Z8 TARGET ENH'!$FH$7:$FJ$38,3,FALSE)) | W9: =IF(E9="","",IF(T9="Not possible",0,IFERROR(L9*N9*P9-L9*F9*G9*U9+L9*F9*G9, "Error"))) | Z9: =IF(E9="",0,1) -> 0
D10: ='A1 Baseline - Terrestrial'!D11 -> 4 | E10: =IF(OR('A1 Baseline - Terrestrial'!E11="",'A1 Baseline - Terrestrial'!O11=0), "",'A1 Baseline - Terrestrial'!E11) | F10: =IF(E10="", "", 'A1 Baseline - Terrestrial'!H11) | G10: =IF(E10="", "", 'A1 Baseline - Terrestrial'!J11) | I10: =IF(E10="","",'A1 Baseline - Terrestrial'!K11) | J10: =IF(OR(E10="",H10=""),"",IF(AND(E10=H10,G10>=P10),"Error - No Enhancement",IF(AND(E10=H10,G10<P10),"Acceptable",IF(F10>N10,"Trading Down - Unacceptable Change",IF(F10=N10,"Error - No Enhancement",'A1 Baseline - Terrestrial'!G11&" - "&IFERROR(VLOOKUP(H10,'Z1 HAB CLASS'!$D$4:$E$45,2,FALSE),"")))))) | K10: =IF(E10="","",IF(AND(E10=H10,G10>=P10),"Error - No Enhancement",IF(AND(E10=H10,G10<P10),'A1 Baseline - Terrestrial'!I11&" - "&'A3 Enhancement - Terrestrial'!O10,IF(F10>N10,"Trading Down - Unacceptable Change",IF(F10=N10,"Error - No Enhancement",IF(AND(E10<>H10,F10<N10),"Lower Distinctiveness Habitat"&" - "&O10,'A1 Baseline - Terrestrial'!I11&" - "&'A3 Enhancement - Terrestrial'!O10)))))) | L10: =IF(E10="","",'A1 Baseline - Terrestrial'!O11) | M10: =IFERROR(VLOOKUP(H10,'Z1 HAB CLASS'!$D$4:$E$45,2,FALSE)," ") | N10: =IFERROR(VLOOKUP(M10,'Z1 HAB CLASS'!$L$3:$N$9,2,FALSE)," ") | P10: =IFERROR(VLOOKUP(O10,'Z3 CONDITION VALUE'!$A$3:$B$5,2,FALSE)," ") | Q10: =IF(OR('A1 Baseline - Terrestrial'!E11="", 'A1 Baseline - Terrestrial'!O11=0), "", 'A1 Baseline - Terrestrial'!I11&"") | R10: =_xludf.TEXTJOIN("/",TRUE,E10,Q10) -> #NAME? | S10: =_xludf.TEXTJOIN("/",TRUE,H10,O10) -> #NAME? | T10: {=IF(OR(R10="",S10=""),"",INDEX('Z8 TARGET ENH'!$F$6:$EO$145,MATCH(R10,'Z8 TARGET ENH'!$B$6:$B$145,0),MATCH(S10,'Z8 TARGET ENH'!$F$2:$EO$2,0)))} -> #NAME? | U10: =IF(E10="","",VLOOKUP(H10,'Z8 TARGET ENH'!$FH$7:$FJ$38,2,FALSE)) | V10: =IF(E10="","",VLOOKUP(H10,'Z8 TARGET ENH'!$FH$7:$FJ$38,3,FALSE)) | W10: =IF(E10="","",IF(T10="Not possible",0,IFERROR(L10*N10*P10-L10*F10*G10*U10+L10*F10*G10, "Error"))) | Z10: =IF(E10="",0,1) -> 0
D11: ='A1 Baseline - Terrestrial'!D12 -> 5 | E11: =IF(OR('A1 Baseline - Terrestrial'!E12="",'A1 Baseline - Terrestrial'!O12=0), "",'A1 Baseline - Terrestrial'!E12) | F11: =IF(E11="", "", 'A1 Baseline - Terrestrial'!H12) | G11: =IF(E11="", "", 'A1 Baseline - Terrestrial'!J12) | I11: =IF(E11="","",'A1 Baseline - Terrestrial'!K12) | J11: =IF(OR(E11="",H11=""),"",IF(AND(E11=H11,G11>=P11),"Error - No Enhancement",IF(AND(E11=H11,G11<P11),"Acceptable",IF(F11>N11,"Trading Down - Unacceptable Change",IF(F11=N11,"Error - No Enhancement",'A1 Baseline - Terrestrial'!G12&" - "&IFERROR(VLOOKUP(H11,'Z1 HAB CLASS'!$D$4:$E$45,2,FALSE),"")))))) | K11: =IF(E11="","",IF(AND(E11=H11,G11>=P11),"Error - No Enhancement",IF(AND(E11=H11,G11<P11),'A1 Baseline - Terrestrial'!I12&" - "&'A3 Enhancement - Terrestrial'!O11,IF(F11>N11,"Trading Down - Unacceptable Change",IF(F11=N11,"Error - No Enhancement",IF(AND(E11<>H11,F11<N11),"Lower Distinctiveness Habitat"&" - "&O11,'A1 Baseline - Terrestrial'!I12&" - "&'A3 Enhancement - Terrestrial'!O11)))))) | L11: =IF(E11="","",'A1 Baseline - Terrestrial'!O12) | M11: =IFERROR(VLOOKUP(H11,'Z1 HAB CLASS'!$D$4:$E$45,2,FALSE)," ") | N11: =IFERROR(VLOOKUP(M11,'Z1 HAB CLASS'!$L$3:$N$9,2,FALSE)," ") | P11: =IFERROR(VLOOKUP(O11,'Z3 CONDITION VALUE'!$A$3:$B$5,2,FALSE)," ") | Q11: =IF(OR('A1 Baseline - Terrestrial'!E12="", 'A1 Baseline - Terrestrial'!O12=0), "", 'A1 Baseline - Terrestrial'!I12&"") | R11: =_xludf.TEXTJOIN("/",TRUE,E11,Q11) -> #NAME? | S11: =_xludf.TEXTJOIN("/",TRUE,H11,O11) -> #NAME? | T11: {=IF(OR(R11="",S11=""),"",INDEX('Z8 TARGET ENH'!$F$6:$EO$145,MATCH(R11,'Z8 TARGET ENH'!$B$6:$B$145,0),MATCH(S11,'Z8 TARGET ENH'!$F$2:$EO$2,0)))} -> #NAME? | U11: =IF(E11="","",VLOOKUP(H11,'Z8 TARGET ENH'!$FH$7:$FJ$38,2,FALSE)) | V11: =IF(E11="","",VLOOKUP(H11,'Z8 TARGET ENH'!$FH$7:$FJ$38,3,FALSE)) | W11: =IF(E11="","",IF(T11="Not possible",0,IFERROR(L11*N11*P11-L11*F11*G11*U11+L11*F11*G11, "Error"))) | Z11: =IF(E11="",0,1) -> 0
D12: ='A1 Baseline - Terrestrial'!D13 -> 6 | E12: =IF(OR('A1 Baseline - Terrestrial'!E13="",'A1 Baseline - Terrestrial'!O13=0), "",'A1 Baseline - Terrestrial'!E13) | F12: =IF(E12="", "", 'A1 Baseline - Terrestrial'!H13) | G12: =IF(E12="", "", 'A1 Baseline - Terrestrial'!J13) | I12: =IF(E12="","",'A1 Baseline - Terrestrial'!K13) | J12: =IF(OR(E12="",H12=""),"",IF(AND(E12=H12,G12>=P12),"Error - No Enhancement",IF(AND(E12=H12,G12<P12),"Acceptable",IF(F12>N12,"Trading Down - Unacceptable Change",IF(F12=N12,"Error - No Enhancement",'A1 Baseline - Terrestrial'!G13&" - "&IFERROR(VLOOKUP(H12,'Z1 HAB CLASS'!$D$4:$E$45,2,FALSE),"")))))) | K12: =IF(E12="","",IF(AND(E12=H12,G12>=P12),"Error - No Enhancement",IF(AND(E12=H12,G12<P12),'A1 Baseline - Terrestrial'!I13&" - "&'A3 Enhancement - Terrestrial'!O12,IF(F12>N12,"Trading Down - Unacceptable Change",IF(F12=N12,"Error - No Enhancement",IF(AND(E12<>H12,F12<N12),"Lower Distinctiveness Habitat"&" - "&O12,'A1 Baseline - Terrestrial'!I13&" - "&'A3 Enhancement - Terrestrial'!O12)))))) | L12: =IF(E12="","",'A1 Baseline - Terrestrial'!O13) | M12: =IFERROR(VLOOKUP(H12,'Z1 HAB CLASS'!$D$4:$E$45,2,FALSE)," ") | N12: =IFERROR(VLOOKUP(M12,'Z1 HAB CLASS'!$L$3:$N$9,2,FALSE)," ") | P12: =IFERROR(VLOOKUP(O12,'Z3 CONDITION VALUE'!$A$3:$B$5,2,FALSE)," ") | Q12: =IF(OR('A1 Baseline - Terrestrial'!E13="", 'A1 Baseline - Terrestrial'!O13=0), "", 'A1 Baseline - Terrestrial'!I13&"") | R12: =_xludf.TEXTJOIN("/",TRUE,E12,Q12) -> #NAME? | S12: =_xludf.TEXTJOIN("/",TRUE,H12,O12) -> #NAME? | T12: {=IF(OR(R12="",S12=""),"",INDEX('Z8 TARGET ENH'!$F$6:$EO$145,MATCH(R12,'Z8 TARGET ENH'!$B$6:$B$145,0),MATCH(S12,'Z8 TARGET ENH'!$F$2:$EO$2,0)))} -> #NAME? | U12: =IF(E12="","",VLOOKUP(H12,'Z8 TARGET ENH'!$FH$7:$FJ$38,2,FALSE)) | V12: =IF(E12="","",VLOOKUP(H12,'Z8 TARGET ENH'!$FH$7:$FJ$38,3,FALSE)) | W12: =IF(E12="","",IF(T12="Not possible",0,IFERROR(L12*N12*P12-L12*F12*G12*U12+L12*F12*G12, "Error"))) | Z12: =IF(E12="",0,1) -> 0
D13: ='A1 Baseline - Terrestrial'!D14 -> 7 | E13: =IF(OR('A1 Baseline - Terrestrial'!E14="",'A1 Baseline - Terrestrial'!O14=0), "",'A1 Baseline - Terrestrial'!E14) | F13: =IF(E13="", "", 'A1 Baseline - Terrestrial'!H14) | G13: =IF(E13="", "", 'A1 Baseline - Terrestrial'!J14) | I13: =IF(E13="","",'A1 Baseline - Terrestrial'!K14) | J13: =IF(OR(E13="",H13=""),"",IF(AND(E13=H13,G13>=P13),"Error - No Enhancement",IF(AND(E13=H13,G13<P13),"Acceptable",IF(F13>N13,"Trading Down - Unacceptable Change",IF(F13=N13,"Error - No Enhancement",'A1 Baseline - Terrestrial'!G14&" - "&IFERROR(VLOOKUP(H13,'Z1 HAB CLASS'!$D$4:$E$45,2,FALSE),"")))))) | K13: =IF(E13="","",IF(AND(E13=H13,G13>=P13),"Error - No Enhancement",IF(AND(E13=H13,G13<P13),'A1 Baseline - Terrestrial'!I14&" - "&'A3 Enhancement - Terrestrial'!O13,IF(F13>N13,"Trading Down - Unacceptable Change",IF(F13=N13,"Error - No Enhancement",IF(AND(E13<>H13,F13<N13),"Lower Distinctiveness Habitat"&" - "&O13,'A1 Baseline - Terrestrial'!I14&" - "&'A3 Enhancement - Terrestrial'!O13)))))) | L13: =IF(E13="","",'A1 Baseline - Terrestrial'!O14) | M13: =IFERROR(VLOOKUP(H13,'Z1 HAB CLASS'!$D$4:$E$45,2,FALSE)," ") | N13: =IFERROR(VLOOKUP(M13,'Z1 HAB CLASS'!$L$3:$N$9,2,FALSE)," ") | P13: =IFERROR(VLOOKUP(O13,'Z3 CONDITION VALUE'!$A$3:$B$5,2,FALSE)," ") | Q13: =IF(OR('A1 Baseline - Terrestrial'!E14="", 'A1 Baseline - Terrestrial'!O14=0), "", 'A1 Baseline - Terrestrial'!I14&"") | R13: =_xludf.TEXTJOIN("/",TRUE,E13,Q13) -> #NAME? | S13: =_xludf.TEXTJOIN("/",TRUE,H13,O13) -> #NAME? | T13: {=IF(OR(R13="",S13=""),"",INDEX('Z8 TARGET ENH'!$F$6:$EO$145,MATCH(R13,'Z8 TARGET ENH'!$B$6:$B$145,0),MATCH(S13,'Z8 TARGET ENH'!$F$2:$EO$2,0)))} -> #NAME? | U13: =IF(E13="","",VLOOKUP($H$8,'Z8 TARGET ENH'!$FH$7:$FJ$38,2,FALSE)) | V13: =IF(E13="","",VLOOKUP(H13,'Z8 TARGET ENH'!$FH$7:$FJ$38,3,FALSE)) | W13: =IF(E13="","",IF(T13="Not possible",0,IFERROR(L13*N13*P13-L13*F13*G13*U13+L13*F13*G13, "Error"))) | Z13: =IF(E13="",0,1) -> 0
D14: ='A1 Baseline - Terrestrial'!D15 -> 8 | E14: =IF(OR('A1 Baseline - Terrestrial'!E15="",'A1 Baseline - Terrestrial'!O15=0), "",'A1 Baseline - Terrestrial'!E15) | F14: =IF(E14="", "", 'A1 Baseline - Terrestrial'!H15) | G14: =IF(E14="", "", 'A1 Baseline - Terrestrial'!J15) | I14: =IF(E14="","",'A1 Baseline - Terrestrial'!K15) | J14: =IF(OR(E14="",H14=""),"",IF(AND(E14=H14,G14>=P14),"Error - No Enhancement",IF(AND(E14=H14,G14<P14),"Acceptable",IF(F14>N14,"Trading Down - Unacceptable Change",IF(F14=N14,"Error - No Enhancement",'A1 Baseline - Terrestrial'!G15&" - "&IFERROR(VLOOKUP(H14,'Z1 HAB CLASS'!$D$4:$E$45,2,FALSE),"")))))) | K14: =IF(E14="","",IF(AND(E14=H14,G14>=P14),"Error - No Enhancement",IF(AND(E14=H14,G14<P14),'A1 Baseline - Terrestrial'!I15&" - "&'A3 Enhancement - Terrestrial'!O14,IF(F14>N14,"Trading Down - Unacceptable Change",IF(F14=N14,"Error - No Enhancement",IF(AND(E14<>H14,F14<N14),"Lower Distinctiveness Habitat"&" - "&O14,'A1 Baseline - Terrestrial'!I15&" - "&'A3 Enhancement - Terrestrial'!O14)))))) | L14: =IF(E14="","",'A1 Baseline - Terrestrial'!O15) | M14: =IFERROR(VLOOKUP(H14,'Z1 HAB CLASS'!$D$4:$E$45,2,FALSE)," ") | N14: =IFERROR(VLOOKUP(M14,'Z1 HAB CLASS'!$L$3:$N$9,2,FALSE)," ") | P14: =IFERROR(VLOOKUP(O14,'Z3 CONDITION VALUE'!$A$3:$B$5,2,FALSE)," ") | Q14: =IF(OR('A1 Baseline - Terrestrial'!E15="", 'A1 Baseline - Terrestrial'!O15=0), "", 'A1 Baseline - Terrestrial'!I15&"") | R14: =_xludf.TEXTJOIN("/",TRUE,E14,Q14) -> #NAME? | S14: =_xludf.TEXTJOIN("/",TRUE,H14,O14) -> #NAME? | T14: {=IF(OR(R14="",S14=""),"",INDEX('Z8 TARGET ENH'!$F$6:$EO$145,MATCH(R14,'Z8 TARGET ENH'!$B$6:$B$145,0),MATCH(S14,'Z8 TARGET ENH'!$F$2:$EO$2,0)))} -> #NAME? | U14: =IF(E14="","",VLOOKUP($H$8,'Z8 TARGET ENH'!$FH$7:$FJ$38,2,FALSE)) | V14: =IF(E14="","",VLOOKUP(H14,'Z8 TARGET ENH'!$FH$7:$FJ$38,3,FALSE)) | W14: =IF(E14="","",IF(T14="Not possible",0,IFERROR(L14*N14*P14-L14*F14*G14*U14+L14*F14*G14, "Error"))) | Z14: =IF(E14="",0,1) -> 0
D15: ='A1 Baseline - Terrestrial'!D16 -> 9 | E15: =IF(OR('A1 Baseline - Terrestrial'!E16="",'A1 Baseline - Terrestrial'!O16=0), "",'A1 Baseline - Terrestrial'!E16) | F15: =IF(E15="", "", 'A1 Baseline - Terrestrial'!H16) | G15: =IF(E15="", "", 'A1 Baseline - Terrestrial'!J16) | I15: =IF(E15="","",'A1 Baseline - Terrestrial'!K16) | J15: =IF(OR(E15="",H15=""),"",IF(AND(E15=H15,G15>=P15),"Error - No Enhancement",IF(AND(E15=H15,G15<P15),"Acceptable",IF(F15>N15,"Trading Down - Unacceptable Change",IF(F15=N15,"Error - No Enhancement",'A1 Baseline - Terrestrial'!G16&" - "&IFERROR(VLOOKUP(H15,'Z1 HAB CLASS'!$D$4:$E$45,2,FALSE),"")))))) | K15: =IF(E15="","",IF(AND(E15=H15,G15>=P15),"Error - No Enhancement",IF(AND(E15=H15,G15<P15),'A1 Baseline - Terrestrial'!I16&" - "&'A3 Enhancement - Terrestrial'!O15,IF(F15>N15,"Trading Down - Unacceptable Change",IF(F15=N15,"Error - No Enhancement",IF(AND(E15<>H15,F15<N15),"Lower Distinctiveness Habitat"&" - "&O15,'A1 Baseline - Terrestrial'!I16&" - "&'A3 Enhancement - Terrestrial'!O15)))))) | L15: =IF(E15="","",'A1 Baseline - Terrestrial'!O16) | M15: =IFERROR(VLOOKUP(H15,'Z1 HAB CLASS'!$D$4:$E$45,2,FALSE)," ") | N15: =IFERROR(VLOOKUP(M15,'Z1 HAB CLASS'!$L$3:$N$9,2,FALSE)," ") | P15: =IFERROR(VLOOKUP(O15,'Z3 CONDITION VALUE'!$A$3:$B$5,2,FALSE)," ") | Q15: =IF(OR('A1 Baseline - Terrestrial'!E16="", 'A1 Baseline - Terrestrial'!O16=0), "", 'A1 Baseline - Terrestrial'!I16&"") | R15: =_xludf.TEXTJOIN("/",TRUE,E15,Q15) -> #NAME? | S15: =_xludf.TEXTJOIN("/",TRUE,H15,O15) -> #NAME? | T15: {=IF(OR(R15="",S15=""),"",INDEX('Z8 TARGET ENH'!$F$6:$EO$145,MATCH(R15,'Z8 TARGET ENH'!$B$6:$B$145,0),MATCH(S15,'Z8 TARGET ENH'!$F$2:$EO$2,0)))} -> #NAME? | U15: =IF(E15="","",VLOOKUP($H$8,'Z8 TARGET ENH'!$FH$7:$FJ$38,2,FALSE)) | V15: =IF(E15="","",VLOOKUP(H15,'Z8 TARGET ENH'!$FH$7:$FJ$38,3,FALSE)) | W15: =IF(E15="","",IF(T15="Not possible",0,IFERROR(L15*N15*P15-L15*F15*G15*U15+L15*F15*G15, "Error"))) | Z15: =IF(E15="",0,1) -> 0
D16: ='A1 Baseline - Terrestrial'!D17 -> 10 | E16: =IF(OR('A1 Baseline - Terrestrial'!E17="",'A1 Baseline - Terrestrial'!O17=0), "",'A1 Baseline - Terrestrial'!E17) | F16: =IF(E16="", "", 'A1 Baseline - Terrestrial'!H17) | G16: =IF(E16="", "", 'A1 Baseline - Terrestrial'!J17) | I16: =IF(E16="","",'A1 Baseline - Terrestrial'!K17) | J16: =IF(OR(E16="",H16=""),"",IF(AND(E16=H16,G16>=P16),"Error - No Enhancement",IF(AND(E16=H16,G16<P16),"Acceptable",IF(F16>N16,"Trading Down - Unacceptable Change",IF(F16=N16,"Error - No Enhancement",'A1 Baseline - Terrestrial'!G17&" - "&IFERROR(VLOOKUP(H16,'Z1 HAB CLASS'!$D$4:$E$45,2,FALSE),"")))))) | K16: =IF(E16="","",IF(AND(E16=H16,G16>=P16),"Error - No Enhancement",IF(AND(E16=H16,G16<P16),'A1 Baseline - Terrestrial'!I17&" - "&'A3 Enhancement - Terrestrial'!O16,IF(F16>N16,"Trading Down - Unacceptable Change",IF(F16=N16,"Error - No Enhancement",IF(AND(E16<>H16,F16<N16),"Lower Distinctiveness Habitat"&" - "&O16,'A1 Baseline - Terrestrial'!I17&" - "&'A3 Enhancement - Terrestrial'!O16)))))) | L16: =IF(E16="","",'A1 Baseline - Terrestrial'!O17) | M16: =IFERROR(VLOOKUP(H16,'Z1 HAB CLASS'!$D$4:$E$45,2,FALSE)," ") | N16: =IFERROR(VLOOKUP(M16,'Z1 HAB CLASS'!$L$3:$N$9,2,FALSE)," ") | P16: =IFERROR(VLOOKUP(O16,'Z3 CONDITION VALUE'!$A$3:$B$5,2,FALSE)," ") | Q16: =IF(OR('A1 Baseline - Terrestrial'!E17="", 'A1 Baseline - Terrestrial'!O17=0), "", 'A1 Baseline - Terrestrial'!I17&"") | R16: =_xludf.TEXTJOIN("/",TRUE,E16,Q16) -> #NAME? | S16: =_xludf.TEXTJOIN("/",TRUE,H16,O16) -> #NAME? | T16: {=IF(OR(R16="",S16=""),"",INDEX('Z8 TARGET ENH'!$F$6:$EO$145,MATCH(R16,'Z8 TARGET ENH'!$B$6:$B$145,0),MATCH(S16,'Z8 TARGET ENH'!$F$2:$EO$2,0)))} -> #NAME? | U16: =IF(E16="","",VLOOKUP($H$8,'Z8 TARGET ENH'!$FH$7:$FJ$38,2,FALSE)) | V16: =IF(E16="","",VLOOKUP(H16,'Z8 TARGET ENH'!$FH$7:$FJ$38,3,FALSE)) | W16: =IF(E16="","",IF(T16="Not possible",0,IFERROR(L16*N16*P16-L16*F16*G16*U16+L16*F16*G16, "Error"))) | Z16: =IF(E16="",0,1) -> 0
D17: ='A1 Baseline - Terrestrial'!D18 -> 11 | E17: =IF(OR('A1 Baseline - Terrestrial'!E18="",'A1 Baseline - Terrestrial'!O18=0), "",'A1 Baseline - Terrestrial'!E18) | F17: =IF(E17="", "", 'A1 Baseline - Terrestrial'!H18) | G17: =IF(E17="", "", 'A1 Baseline - Terrestrial'!J18) | I17: =IF(E17="","",'A1 Baseline - Terrestrial'!K18) | J17: =IF(OR(E17="",H17=""),"",IF(AND(E17=H17,G17>=P17),"Error - No Enhancement",IF(AND(E17=H17,G17<P17),"Acceptable",IF(F17>N17,"Trading Down - Unacceptable Change",IF(F17=N17,"Error - No Enhancement",'A1 Baseline - Terrestrial'!G18&" - "&IFERROR(VLOOKUP(H17,'Z1 HAB CLASS'!$D$4:$E$45,2,FALSE),"")))))) | K17: =IF(E17="","",IF(AND(E17=H17,G17>=P17),"Error - No Enhancement",IF(AND(E17=H17,G17<P17),'A1 Baseline - Terrestrial'!I18&" - "&'A3 Enhancement - Terrestrial'!O17,IF(F17>N17,"Trading Down - Unacceptable Change",IF(F17=N17,"Error - No Enhancement",IF(AND(E17<>H17,F17<N17),"Lower Distinctiveness Habitat"&" - "&O17,'A1 Baseline - Terrestrial'!I18&" - "&'A3 Enhancement - Terrestrial'!O17)))))) | L17: =IF(E17="","",'A1 Baseline - Terrestrial'!O18) | M17: =IFERROR(VLOOKUP(H17,'Z1 HAB CLASS'!$D$4:$E$45,2,FALSE)," ") | N17: =IFERROR(VLOOKUP(M17,'Z1 HAB CLASS'!$L$3:$N$9,2,FALSE)," ") | P17: =IFERROR(VLOOKUP(O17,'Z3 CONDITION VALUE'!$A$3:$B$5,2,FALSE)," ") | Q17: =IF(OR('A1 Baseline - Terrestrial'!E18="", 'A1 Baseline - Terrestrial'!O18=0), "", 'A1 Baseline - Terrestrial'!I18&"") | R17: =_xludf.TEXTJOIN("/",TRUE,E17,Q17) -> #NAME? | S17: =_xludf.TEXTJOIN("/",TRUE,H17,O17) -> #NAME? | T17: {=IF(OR(R17="",S17=""),"",INDEX('Z8 TARGET ENH'!$F$6:$EO$145,MATCH(R17,'Z8 TARGET ENH'!$B$6:$B$145,0),MATCH(S17,'Z8 TARGET ENH'!$F$2:$EO$2,0)))} -> #NAME? | U17: =IF(E17="","",VLOOKUP($H$8,'Z8 TARGET ENH'!$FH$7:$FJ$38,2,FALSE)) | V17: =IF(E17="","",VLOOKUP(H17,'Z8 TARGET ENH'!$FH$7:$FJ$38,3,FALSE)) | W17: =IF(E17="","",IF(T17="Not possible",0,IFERROR(L17*N17*P17-L17*F17*G17*U17+L17*F17*G17, "Error"))) | Z17: =IF(E17="",0,1) -> 0
D18: ='A1 Baseline - Terrestrial'!D19 -> 12 | E18: =IF(OR('A1 Baseline - Terrestrial'!E19="",'A1 Baseline - Terrestrial'!O19=0), "",'A1 Baseline - Terrestrial'!E19) | F18: =IF(E18="", "", 'A1 Baseline - Terrestrial'!H19) | G18: =IF(E18="", "", 'A1 Baseline - Terrestrial'!J19) | I18: =IF(E18="","",'A1 Baseline - Terrestrial'!K19) | J18: =IF(OR(E18="",H18=""),"",IF(AND(E18=H18,G18>=P18),"Error - No Enhancement",IF(AND(E18=H18,G18<P18),"Acceptable",IF(F18>N18,"Trading Down - Unacceptable Change",IF(F18=N18,"Error - No Enhancement",'A1 Baseline - Terrestrial'!G19&" - "&IFERROR(VLOOKUP(H18,'Z1 HAB CLASS'!$D$4:$E$45,2,FALSE),"")))))) | K18: =IF(E18="","",IF(AND(E18=H18,G18>=P18),"Error - No Enhancement",IF(AND(E18=H18,G18<P18),'A1 Baseline - Terrestrial'!I19&" - "&'A3 Enhancement - Terrestrial'!O18,IF(F18>N18,"Trading Down - Unacceptable Change",IF(F18=N18,"Error - No Enhancement",IF(AND(E18<>H18,F18<N18),"Lower Distinctiveness Habitat"&" - "&O18,'A1 Baseline - Terrestrial'!I19&" - "&'A3 Enhancement - Terrestrial'!O18)))))) | L18: =IF(E18="","",'A1 Baseline - Terrestrial'!O19) | M18: =IFERROR(VLOOKUP(H18,'Z1 HAB CLASS'!$D$4:$E$45,2,FALSE)," ") | N18: =IFERROR(VLOOKUP(M18,'Z1 HAB CLASS'!$L$3:$N$9,2,FALSE)," ") | P18: =IFERROR(VLOOKUP(O18,'Z3 CONDITION VALUE'!$A$3:$B$5,2,FALSE)," ") | Q18: =IF(OR('A1 Baseline - Terrestrial'!E19="", 'A1 Baseline - Terrestrial'!O19=0), "", 'A1 Baseline - Terrestrial'!I19&"") | R18: =_xludf.TEXTJOIN("/",TRUE,E18,Q18) -> #NAME? | S18: =_xludf.TEXTJOIN("/",TRUE,H18,O18) -> #NAME? | T18: {=IF(OR(R18="",S18=""),"",INDEX('Z8 TARGET ENH'!$F$6:$EO$145,MATCH(R18,'Z8 TARGET ENH'!$B$6:$B$145,0),MATCH(S18,'Z8 TARGET ENH'!$F$2:$EO$2,0)))} -> #NAME? | U18: =IF(E18="","",VLOOKUP($H$8,'Z8 TARGET ENH'!$FH$7:$FJ$38,2,FALSE)) | V18: =IF(E18="","",VLOOKUP(H18,'Z8 TARGET ENH'!$FH$7:$FJ$38,3,FALSE)) | W18: =IF(E18="","",IF(T18="Not possible",0,IFERROR(L18*N18*P18-L18*F18*G18*U18+L18*F18*G18, "Error"))) | Z18: =IF(E18="",0,1) -> 0
D19: ='A1 Baseline - Terrestrial'!D20 -> 13 | E19: =IF(OR('A1 Baseline - Terrestrial'!E20="",'A1 Baseline - Terrestrial'!O20=0), "",'A1 Baseline - Terrestrial'!E20) | F19: =IF(E19="", "", 'A1 Baseline - Terrestrial'!H20) | G19: =IF(E19="", "", 'A1 Baseline - Terrestrial'!J20) | I19: =IF(E19="","",'A1 Baseline - Terrestrial'!K20) | J19: =IF(OR(E19="",H19=""),"",IF(AND(E19=H19,G19>=P19),"Error - No Enhancement",IF(AND(E19=H19,G19<P19),"Acceptable",IF(F19>N19,"Trading Down - Unacceptable Change",IF(F19=N19,"Error - No Enhancement",'A1 Baseline - Terrestrial'!G20&" - "&IFERROR(VLOOKUP(H19,'Z1 HAB CLASS'!$D$4:$E$45,2,FALSE),"")))))) | K19: =IF(E19="","",IF(AND(E19=H19,G19>=P19),"Error - No Enhancement",IF(AND(E19=H19,G19<P19),'A1 Baseline - Terrestrial'!I20&" - "&'A3 Enhancement - Terrestrial'!O19,IF(F19>N19,"Trading Down - Unacceptable Change",IF(F19=N19,"Error - No Enhancement",IF(AND(E19<>H19,F19<N19),"Lower Distinctiveness Habitat"&" - "&O19,'A1 Baseline - Terrestrial'!I20&" - "&'A3 Enhancement - Terrestrial'!O19)))))) | L19: =IF(E19="","",'A1 Baseline - Terrestrial'!O20) | M19: =IFERROR(VLOOKUP(H19,'Z1 HAB CLASS'!$D$4:$E$45,2,FALSE)," ") | N19: =IFERROR(VLOOKUP(M19,'Z1 HAB CLASS'!$L$3:$N$9,2,FALSE)," ") | P19: =IFERROR(VLOOKUP(O19,'Z3 CONDITION VALUE'!$A$3:$B$5,2,FALSE)," ") | Q19: =IF(OR('A1 Baseline - Terrestrial'!E20="", 'A1 Baseline - Terrestrial'!O20=0), "", 'A1 Baseline - Terrestrial'!I20&"") | R19: =_xludf.TEXTJOIN("/",TRUE,E19,Q19) -> #NAME? | S19: =_xludf.TEXTJOIN("/",TRUE,H19,O19) -> #NAME? | T19: {=IF(OR(R19="",S19=""),"",INDEX('Z8 TARGET ENH'!$F$6:$EO$145,MATCH(R19,'Z8 TARGET ENH'!$B$6:$B$145,0),MATCH(S19,'Z8 TARGET ENH'!$F$2:$EO$2,0)))} -> #NAME? | U19: =IF(E19="","",VLOOKUP($H$8,'Z8 TARGET ENH'!$FH$7:$FJ$38,2,FALSE)) | V19: =IF(E19="","",VLOOKUP(H19,'Z8 TARGET ENH'!$FH$7:$FJ$38,3,FALSE)) | W19: =IF(E19="","",IF(T19="Not possible",0,IFERROR(L19*N19*P19-L19*F19*G19*U19+L19*F19*G19, "Error"))) | Z19: =IF(E19="",0,1) -> 0
D20: ='A1 Baseline - Terrestrial'!D21 -> 14 | E20: =IF(OR('A1 Baseline - Terrestrial'!E21="",'A1 Baseline - Terrestrial'!O21=0), "",'A1 Baseline - Terrestrial'!E21) | F20: =IF(E20="", "", 'A1 Baseline - Terrestrial'!H21) | G20: =IF(E20="", "", 'A1 Baseline - Terrestrial'!J21) | I20: =IF(E20="","",'A1 Baseline - Terrestrial'!K21) | J20: =IF(OR(E20="",H20=""),"",IF(AND(E20=H20,G20>=P20),"Error - No Enhancement",IF(AND(E20=H20,G20<P20),"Acceptable",IF(F20>N20,"Trading Down - Unacceptable Change",IF(F20=N20,"Error - No Enhancement",'A1 Baseline - Terrestrial'!G21&" - "&IFERROR(VLOOKUP(H20,'Z1 HAB CLASS'!$D$4:$E$45,2,FALSE),"")))))) | K20: =IF(E20="","",IF(AND(E20=H20,G20>=P20),"Error - No Enhancement",IF(AND(E20=H20,G20<P20),'A1 Baseline - Terrestrial'!I21&" - "&'A3 Enhancement - Terrestrial'!O20,IF(F20>N20,"Trading Down - Unacceptable Change",IF(F20=N20,"Error - No Enhancement",IF(AND(E20<>H20,F20<N20),"Lower Distinctiveness Habitat"&" - "&O20,'A1 Baseline - Terrestrial'!I21&" - "&'A3 Enhancement - Terrestrial'!O20)))))) | L20: =IF(E20="","",'A1 Baseline - Terrestrial'!O21) | M20: =IFERROR(VLOOKUP(H20,'Z1 HAB CLASS'!$D$4:$E$45,2,FALSE)," ") | N20: =IFERROR(VLOOKUP(M20,'Z1 HAB CLASS'!$L$3:$N$9,2,FALSE)," ") | P20: =IFERROR(VLOOKUP(O20,'Z3 CONDITION VALUE'!$A$3:$B$5,2,FALSE)," ") | Q20: =IF(OR('A1 Baseline - Terrestrial'!E21="", 'A1 Baseline - Terrestrial'!O21=0), "", 'A1 Baseline - Terrestrial'!I21&"") | R20: =_xludf.TEXTJOIN("/",TRUE,E20,Q20) -> #NAME? | S20: =_xludf.TEXTJOIN("/",TRUE,H20,O20) -> #NAME? | T20: {=IF(OR(R20="",S20=""),"",INDEX('Z8 TARGET ENH'!$F$6:$EO$145,MATCH(R20,'Z8 TARGET ENH'!$B$6:$B$145,0),MATCH(S20,'Z8 TARGET ENH'!$F$2:$EO$2,0)))} -> #NAME? | U20: =IF(E20="","",VLOOKUP($H$8,'Z8 TARGET ENH'!$FH$7:$FJ$38,2,FALSE)) | V20: =IF(E20="","",VLOOKUP(H20,'Z8 TARGET ENH'!$FH$7:$FJ$38,3,FALSE)) | W20: =IF(E20="","",IF(T20="Not possible",0,IFERROR(L20*N20*P20-L20*F20*G20*U20+L20*F20*G20, "Error"))) | Z20: =IF(E20="",0,1) -> 0
D21: ='A1 Baseline - Terrestrial'!D22 -> 15 | E21: =IF(OR('A1 Baseline - Terrestrial'!E22="",'A1 Baseline - Terrestrial'!O22=0), "",'A1 Baseline - Terrestrial'!E22) | F21: =IF(E21="", "", 'A1 Baseline - Terrestrial'!H22) | G21: =IF(E21="", "", 'A1 Baseline - Terrestrial'!J22) | I21: =IF(E21="","",'A1 Baseline - Terrestrial'!K22) | J21: =IF(OR(E21="",H21=""),"",IF(AND(E21=H21,G21>=P21),"Error - No Enhancement",IF(AND(E21=H21,G21<P21),"Acceptable",IF(F21>N21,"Trading Down - Unacceptable Change",IF(F21=N21,"Error - No Enhancement",'A1 Baseline - Terrestrial'!G22&" - "&IFERROR(VLOOKUP(H21,'Z1 HAB CLASS'!$D$4:$E$45,2,FALSE),"")))))) | K21: =IF(E21="","",IF(AND(E21=H21,G21>=P21),"Error - No Enhancement",IF(AND(E21=H21,G21<P21),'A1 Baseline - Terrestrial'!I22&" - "&'A3 Enhancement - Terrestrial'!O21,IF(F21>N21,"Trading Down - Unacceptable Change",IF(F21=N21,"Error - No Enhancement",IF(AND(E21<>H21,F21<N21),"Lower Distinctiveness Habitat"&" - "&O21,'A1 Baseline - Terrestrial'!I22&" - "&'A3 Enhancement - Terrestrial'!O21)))))) | L21: =IF(E21="","",'A1 Baseline - Terrestrial'!O22) | M21: =IFERROR(VLOOKUP(H21,'Z1 HAB CLASS'!$D$4:$E$45,2,FALSE)," ") | N21: =IFERROR(VLOOKUP(M21,'Z1 HAB CLASS'!$L$3:$N$9,2,FALSE)," ") | P21: =IFERROR(VLOOKUP(O21,'Z3 CONDITION VALUE'!$A$3:$B$5,2,FALSE)," ") | Q21: =IF(OR('A1 Baseline - Terrestrial'!E22="", 'A1 Baseline - Terrestrial'!O22=0), "", 'A1 Baseline - Terrestrial'!I22&"") | R21: =_xludf.TEXTJOIN("/",TRUE,E21,Q21) -> #NAME? | S21: =_xludf.TEXTJOIN("/",TRUE,H21,O21) -> #NAME? | T21: {=IF(OR(R21="",S21=""),"",INDEX('Z8 TARGET ENH'!$F$6:$EO$145,MATCH(R21,'Z8 TARGET ENH'!$B$6:$B$145,0),MATCH(S21,'Z8 TARGET ENH'!$F$2:$EO$2,0)))} -> #NAME? | U21: =IF(E21="","",VLOOKUP($H$8,'Z8 TARGET ENH'!$FH$7:$FJ$38,2,FALSE)) | V21: =IF(E21="","",VLOOKUP(H21,'Z8 TARGET ENH'!$FH$7:$FJ$38,3,FALSE)) | W21: =IF(E21="","",IF(T21="Not possible",0,IFERROR(L21*N21*P21-L21*F21*G21*U21+L21*F21*G21, "Error"))) | Z21: =IF(E21="",0,1) -> 0
D22: ='A1 Baseline - Terrestrial'!D23 -> 16 | E22: =IF(OR('A1 Baseline - Terrestrial'!E23="",'A1 Baseline - Terrestrial'!O23=0), "",'A1 Baseline - Terrestrial'!E23) | F22: =IF(E22="", "", 'A1 Baseline - Terrestrial'!H23) | G22: =IF(E22="", "", 'A1 Baseline - Terrestrial'!J23) | I22: =IF(E22="","",'A1 Baseline - Terrestrial'!K23) | J22: =IF(OR(E22="",H22=""),"",IF(AND(E22=H22,G22>=P22),"Error - No Enhancement",IF(AND(E22=H22,G22<P22),"Acceptable",IF(F22>N22,"Trading Down - Unacceptable Change",IF(F22=N22,"Error - No Enhancement",'A1 Baseline - Terrestrial'!G23&" - "&IFERROR(VLOOKUP(H22,'Z1 HAB CLASS'!$D$4:$E$45,2,FALSE),"")))))) | K22: =IF(E22="","",IF(AND(E22=H22,G22>=P22),"Error - No Enhancement",IF(AND(E22=H22,G22<P22),'A1 Baseline - Terrestrial'!I23&" - "&'A3 Enhancement - Terrestrial'!O22,IF(F22>N22,"Trading Down - Unacceptable Change",IF(F22=N22,"Error - No Enhancement",IF(AND(E22<>H22,F22<N22),"Lower Distinctiveness Habitat"&" - "&O22,'A1 Baseline - Terrestrial'!I23&" - "&'A3 Enhancement - Terrestrial'!O22)))))) | L22: =IF(E22="","",'A1 Baseline - Terrestrial'!O23) | M22: =IFERROR(VLOOKUP(H22,'Z1 HAB CLASS'!$D$4:$E$45,2,FALSE)," ") | N22: =IFERROR(VLOOKUP(M22,'Z1 HAB CLASS'!$L$3:$N$9,2,FALSE)," ") | P22: =IFERROR(VLOOKUP(O22,'Z3 CONDITION VALUE'!$A$3:$B$5,2,FALSE)," ") | Q22: =IF(OR('A1 Baseline - Terrestrial'!E23="", 'A1 Baseline - Terrestrial'!O23=0), "", 'A1 Baseline - Terrestrial'!I23&"") | R22: =_xludf.TEXTJOIN("/",TRUE,E22,Q22) -> #NAME? | S22: =_xludf.TEXTJOIN("/",TRUE,H22,O22) -> #NAME? | T22: {=IF(OR(R22="",S22=""),"",INDEX('Z8 TARGET ENH'!$F$6:$EO$145,MATCH(R22,'Z8 TARGET ENH'!$B$6:$B$145,0),MATCH(S22,'Z8 TARGET ENH'!$F$2:$EO$2,0)))} -> #NAME? | U22: =IF(E22="","",VLOOKUP($H$8,'Z8 TARGET ENH'!$FH$7:$FJ$38,2,FALSE)) | V22: =IF(E22="","",VLOOKUP(H22,'Z8 TARGET ENH'!$FH$7:$FJ$38,3,FALSE)) | W22: =IF(E22="","",IF(T22="Not possible",0,IFERROR(L22*N22*P22-L22*F22*G22*U22+L22*F22*G22, "Error"))) | Z22: =IF(E22="",0,1) -> 0
D23: ='A1 Baseline - Terrestrial'!D24 -> 17 | E23: =IF(OR('A1 Baseline - Terrestrial'!E24="",'A1 Baseline - Terrestrial'!O24=0), "",'A1 Baseline - Terrestrial'!E24) | F23: =IF(E23="", "", 'A1 Baseline - Terrestrial'!H24) | G23: =IF(E23="", "", 'A1 Baseline - Terrestrial'!J24) | I23: =IF(E23="","",'A1 Baseline - Terrestrial'!K24) | J23: =IF(OR(E23="",H23=""),"",IF(AND(E23=H23,G23>=P23),"Error - No Enhancement",IF(AND(E23=H23,G23<P23),"Acceptable",IF(F23>N23,"Trading Down - Unacceptable Change",IF(F23=N23,"Error - No Enhancement",'A1 Baseline - Terrestrial'!G24&" - "&IFERROR(VLOOKUP(H23,'Z1 HAB CLASS'!$D$4:$E$45,2,FALSE),"")))))) | K23: =IF(E23="","",IF(AND(E23=H23,G23>=P23),"Error - No Enhancement",IF(AND(E23=H23,G23<P23),'A1 Baseline - Terrestrial'!I24&" - "&'A3 Enhancement - Terrestrial'!O23,IF(F23>N23,"Trading Down - Unacceptable Change",IF(F23=N23,"Error - No Enhancement",IF(AND(E23<>H23,F23<N23),"Lower Distinctiveness Habitat"&" - "&O23,'A1 Baseline - Terrestrial'!I24&" - "&'A3 Enhancement - Terrestrial'!O23)))))) | L23: =IF(E23="","",'A1 Baseline - Terrestrial'!O24) | M23: =IFERROR(VLOOKUP(H23,'Z1 HAB CLASS'!$D$4:$E$45,2,FALSE)," ") | N23: =IFERROR(VLOOKUP(M23,'Z1 HAB CLASS'!$L$3:$N$9,2,FALSE)," ") | P23: =IFERROR(VLOOKUP(O23,'Z3 CONDITION VALUE'!$A$3:$B$5,2,FALSE)," ") | Q23: =IF(OR('A1 Baseline - Terrestrial'!E24="", 'A1 Baseline - Terrestrial'!O24=0), "", 'A1 Baseline - Terrestrial'!I24&"") | R23: =_xludf.TEXTJOIN("/",TRUE,E23,Q23) -> #NAME? | S23: =_xludf.TEXTJOIN("/",TRUE,H23,O23) -> #NAME? | T23: {=IF(OR(R23="",S23=""),"",INDEX('Z8 TARGET ENH'!$F$6:$EO$145,MATCH(R23,'Z8 TARGET ENH'!$B$6:$B$145,0),MATCH(S23,'Z8 TARGET ENH'!$F$2:$EO$2,0)))} -> #NAME? | U23: =IF(E23="","",VLOOKUP($H$8,'Z8 TARGET ENH'!$FH$7:$FJ$38,2,FALSE)) | V23: =IF(E23="","",VLOOKUP(H23,'Z8 TARGET ENH'!$FH$7:$FJ$38,3,FALSE)) | W23: =IF(E23="","",IF(T23="Not possible",0,IFERROR(L23*N23*P23-L23*F23*G23*U23+L23*F23*G23, "Error"))) | Z23: =IF(E23="",0,1) -> 0
D24: ='A1 Baseline - Terrestrial'!D25 -> 18 | E24: =IF(OR('A1 Baseline - Terrestrial'!E25="",'A1 Baseline - Terrestrial'!O25=0), "",'A1 Baseline - Terrestrial'!E25) | F24: =IF(E24="", "", 'A1 Baseline - Terrestrial'!H25) | G24: =IF(E24="", "", 'A1 Baseline - Terrestrial'!J25) | I24: =IF(E24="","",'A1 Baseline - Terrestrial'!K25) | J24: =IF(OR(E24="",H24=""),"",IF(AND(E24=H24,G24>=P24),"Error - No Enhancement",IF(AND(E24=H24,G24<P24),"Acceptable",IF(F24>N24,"Trading Down - Unacceptable Change",IF(F24=N24,"Error - No Enhancement",'A1 Baseline - Terrestrial'!G25&" - "&IFERROR(VLOOKUP(H24,'Z1 HAB CLASS'!$D$4:$E$45,2,FALSE),"")))))) | K24: =IF(E24="","",IF(AND(E24=H24,G24>=P24),"Error - No Enhancement",IF(AND(E24=H24,G24<P24),'A1 Baseline - Terrestrial'!I25&" - "&'A3 Enhancement - Terrestrial'!O24,IF(F24>N24,"Trading Down - Unacceptable Change",IF(F24=N24,"Error - No Enhancement",IF(AND(E24<>H24,F24<N24),"Lower Distinctiveness Habitat"&" - "&O24,'A1 Baseline - Terrestrial'!I25&" - "&'A3 Enhancement - Terrestrial'!O24)))))) | L24: =IF(E24="","",'A1 Baseline - Terrestrial'!O25) | M24: =IFERROR(VLOOKUP(H24,'Z1 HAB CLASS'!$D$4:$E$45,2,FALSE)," ") | N24: =IFERROR(VLOOKUP(M24,'Z1 HAB CLASS'!$L$3:$N$9,2,FALSE)," ") | P24: =IFERROR(VLOOKUP(O24,'Z3 CONDITION VALUE'!$A$3:$B$5,2,FALSE)," ") | Q24: =IF(OR('A1 Baseline - Terrestrial'!E25="", 'A1 Baseline - Terrestrial'!O25=0), "", 'A1 Baseline - Terrestrial'!I25&"") | R24: =_xludf.TEXTJOIN("/",TRUE,E24,Q24) -> #NAME? | S24: =_xludf.TEXTJOIN("/",TRUE,H24,O24) -> #NAME? | T24: {=IF(OR(R24="",S24=""),"",INDEX('Z8 TARGET ENH'!$F$6:$EO$145,MATCH(R24,'Z8 TARGET ENH'!$B$6:$B$145,0),MATCH(S24,'Z8 TARGET ENH'!$F$2:$EO$2,0)))} -> #NAME? | U24: =IF(E24="","",VLOOKUP($H$8,'Z8 TARGET ENH'!$FH$7:$FJ$38,2,FALSE)) | V24: =IF(E24="","",VLOOKUP(H24,'Z8 TARGET ENH'!$FH$7:$FJ$38,3,FALSE)) | W24: =IF(E24="","",IF(T24="Not possible",0,IFERROR(L24*N24*P24-L24*F24*G24*U24+L24*F24*G24, "Error"))) | Z24: =IF(E24="",0,1) -> 0
... D254: ='A1 Baseline - Terrestrial'!D255 -> 248 | E254: =IF(OR('A1 Baseline - Terrestrial'!E255="",'A1 Baseline - Terrestrial'!O255=0), "",'A1 Baseline - Terrestrial'!E255) | F254: =IF(E254="", "", 'A1 Baseline - Terrestrial'!H255) | G254: =IF(E254="", "", 'A1 Baseline - Terrestrial'!J255) | I254: =IF(E254="","",'A1 Baseline - Terrestrial'!K255) | J254: =IF(OR(E254="",H254=""),"",IF(AND(E254=H254,G254>=P254),"Error - No Enhancement",IF(AND(E254=H254,G254<P254),"Acceptable",IF(F254>N254,"Trading Down - Unacceptable Change",IF(F254=N254,"Error - No Enhancement",'A1 Baseline - Terrestrial'!G255&" - "&IFERROR(VLOOKUP(H254,'Z1 HAB CLASS'!$D$4:$E$45,2,FALSE),"")))))) | K254: =IF(E254="","",IF(AND(E254=H254,G254>=P254),"Error - No Enhancement",IF(AND(E254=H254,G254<P254),'A1 Baseline - Terrestrial'!I255&" - "&'A3 Enhancement - Terrestrial'!O254,IF(F254>N254,"Trading Down - Unacceptable Change",IF(F254=N254,"Error - No Enhancement",IF(AND(E254<>H254,F254<N254),"Lower Distinctiveness Habitat"&" - "&O254,'A1 Baseline - Terrestrial'!I255&" - "&'A3 Enhancement - Terrestrial'!O254)))))) | L254: =IF(E254="","",'A1 Baseline - Terrestrial'!O255) | M254: =IFERROR(VLOOKUP(H254,'Z1 HAB CLASS'!$D$4:$E$45,2,FALSE)," ") | N254: =IFERROR(VLOOKUP(M254,'Z1 HAB CLASS'!$L$3:$N$9,2,FALSE)," ") | P254: =IFERROR(VLOOKUP(O254,'Z3 CONDITION VALUE'!$A$3:$B$5,2,FALSE)," ") | Q254: =IF(OR('A1 Baseline - Terrestrial'!E255="", 'A1 Baseline - Terrestrial'!O255=0), "", 'A1 Baseline - Terrestrial'!I255&"") | R254: =_xludf.TEXTJOIN("/",TRUE,E254,Q254) -> #NAME? | S254: =_xludf.TEXTJOIN("/",TRUE,H254,O254) -> #NAME? | T254: {=IF(OR(R254="",S254=""),"",INDEX('Z8 TARGET ENH'!$F$6:$EO$145,MATCH(R254,'Z8 TARGET ENH'!$B$6:$B$145,0),MATCH(S254,'Z8 TARGET ENH'!$F$2:$EO$2,0)))} -> #NAME? | U254: =IF(E254="","",VLOOKUP($H$8,'Z8 TARGET ENH'!$FH$7:$FJ$38,2,FALSE)) | V254: =IF(E254="","",VLOOKUP(H254,'Z8 TARGET ENH'!$FH$7:$FJ$38,3,FALSE)) | W254: =IF(E254="","",IF(T254="Not possible",0,IFERROR(L254*N254*P254-L254*F254*G254*U254+L254*F254*G254, "Error"))) | Z254: =IF(E254="",0,1) -> 0
K255: Total area | L255: =SUM(L7:L254) -> 0 | U255: Total units | W255: =SUM(W7:W254) -> 0 | Z255: 1

Sheet A2 Creation - Terrestrial
W1: 1
D2: POST-DEVELOPMENT | W2: 1
D3: CREATION - TERRESTRIAL HABITATS | W3: 1
W4: 1
E5: Habitats and Areas | G5: Distinctiveness | I5: Condition | K5: Time to Target Condition | L5: Difficulty of Creation | N5: Terrestrial Units Delivered | O5: Justifications and Comments | W5: 1
D6: Ref | E6: Proposed Habitat | F6: Area (ha) | G6: Distinctiveness | H6: Score | I6: Condition | J6: Score | K6: No. Years | L6: Difficulty of Creation | M6: Difficulty Multiplier | W6: =IF(F6="",0,1) -> 1
D7: 1 | E7: Turf | F7: 4 | G7: =IFERROR(VLOOKUP(E7,'Z1 HAB CLASS'!$D$4:$E$45,2,FALSE)," ") -> Extremely low | H7: =IFERROR(VLOOKUP(G7,'Z1 HAB CLASS'!$L$3:$N$9,2,FALSE)," ") -> 0.5 | I7: Good | J7: =IFERROR(VLOOKUP(I7,'Z3 CONDITION VALUE'!$A$3:$B$5,2,FALSE)," ") -> 3 | K7: {=IFERROR(INDEX('Z7 TARGET CREATION'!$C$3:$F$40,MATCH(E7,'Z7 TARGET CREATION'!$B$3:$B$40,0),MATCH(I7,'Z7 TARGET CREATION'!$C$2:$F$2,0)),"")} -> 2 | L7: =IF(E7="","",VLOOKUP(E7,'Z7 TARGET CREATION'!$G$3:$I$40,3,FALSE)) -> Low | M7: =IF(E7="","",VLOOKUP(E7,'Z7 TARGET CREATION'!$G$3:$H$40,2, FALSE)) -> 1 | N7: =IF(E7="","",IF(K7="Not possible",0,F7*H7*J7*M7)) -> 6 | W7: =IF(F7="",0,1) -> 1
D8: 2 | G8: =IFERROR(VLOOKUP(E8,'Z1 HAB CLASS'!$D$4:$E$45,2,FALSE)," ") | H8: =IFERROR(VLOOKUP(G8,'Z1 HAB CLASS'!$L$3:$N$9,2,FALSE)," ") | J8: =IFERROR(VLOOKUP(I8,'Z3 CONDITION VALUE'!$A$3:$B$5,2,FALSE)," ") | K8: {=IFERROR(INDEX('Z7 TARGET CREATION'!$C$3:$F$40,MATCH(E8,'Z7 TARGET CREATION'!$B$3:$B$40,0),MATCH(I8,'Z7 TARGET CREATION'!$C$2:$F$2,0)),"")} | L8: =IF(E8="","",VLOOKUP(E8,'Z7 TARGET CREATION'!$G$3:$I$40,3,FALSE)) | M8: =IF(E8="","",VLOOKUP(E8,'Z7 TARGET CREATION'!$G$3:$H$40,2, FALSE)) | N8: =IF(E8="","",IF(K8="Not possible",0,F8*H8*J8*M8)) | W8: =IF(F8="",0,1) -> 0
D9: 3 | G9: =IFERROR(VLOOKUP(E9,'Z1 HAB CLASS'!$D$4:$E$45,2,FALSE)," ") | H9: =IFERROR(VLOOKUP(G9,'Z1 HAB CLASS'!$L$3:$N$9,2,FALSE)," ") | J9: =IFERROR(VLOOKUP(I9,'Z3 CONDITION VALUE'!$A$3:$B$5,2,FALSE)," ") | K9: {=IFERROR(INDEX('Z7 TARGET CREATION'!$C$3:$F$40,MATCH(E9,'Z7 TARGET CREATION'!$B$3:$B$40,0),MATCH(I9,'Z7 TARGET CREATION'!$C$2:$F$2,0)),"")} | L9: =IF(E9="","",VLOOKUP(E9,'Z7 TARGET CREATION'!$G$3:$I$40,3,FALSE)) | M9: =IF(E9="","",VLOOKUP(E9,'Z7 TARGET CREATION'!$G$3:$H$40,2, FALSE)) | N9: =IF(E9="","",IF(K9="Not possible",0,F9*H9*J9*M9)) | W9: =IF(F9="",0,1) -> 0
D10: 4 | G10: =IFERROR(VLOOKUP(E10,'Z1 HAB CLASS'!$D$4:$E$45,2,FALSE)," ") | H10: =IFERROR(VLOOKUP(G10,'Z1 HAB CLASS'!$L$3:$N$9,2,FALSE)," ") | J10: =IFERROR(VLOOKUP(I10,'Z3 CONDITION VALUE'!$A$3:$B$5,2,FALSE)," ") | K10: {=IFERROR(INDEX('Z7 TARGET CREATION'!$C$3:$F$40,MATCH(E10,'Z7 TARGET CREATION'!$B$3:$B$40,0),MATCH(I10,'Z7 TARGET CREATION'!$C$2:$F$2,0)),"")} | L10: =IF(E10="","",VLOOKUP(E10,'Z7 TARGET CREATION'!$G$3:$I$40,3,FALSE)) | M10: =IF(E10="","",VLOOKUP(E10,'Z7 TARGET CREATION'!$G$3:$H$40,2, FALSE)) | N10: =IF(E10="","",IF(K10="Not possible",0,F10*H10*J10*M10)) | W10: =IF(F10="",0,1) -> 0
D11: 5 | G11: =IFERROR(VLOOKUP(E11,'Z1 HAB CLASS'!$D$4:$E$45,2,FALSE)," ") | H11: =IFERROR(VLOOKUP(G11,'Z1 HAB CLASS'!$L$3:$N$9,2,FALSE)," ") | J11: =IFERROR(VLOOKUP(I11,'Z3 CONDITION VALUE'!$A$3:$B$5,2,FALSE)," ") | K11: {=IFERROR(INDEX('Z7 TARGET CREATION'!$C$3:$F$40,MATCH(E11,'Z7 TARGET CREATION'!$B$3:$B$40,0),MATCH(I11,'Z7 TARGET CREATION'!$C$2:$F$2,0)),"")} | L11: =IF(E11="","",VLOOKUP(E11,'Z7 TARGET CREATION'!$G$3:$I$40,3,FALSE)) | M11: =IF(E11="","",VLOOKUP(E11,'Z7 TARGET CREATION'!$G$3:$H$40,2, FALSE)) | N11: =IF(E11="","",IF(K11="Not possible",0,F11*H11*J11*M11)) | W11: =IF(F11="",0,1) -> 0
D12: 6 | G12: =IFERROR(VLOOKUP(E12,'Z1 HAB CLASS'!$D$4:$E$45,2,FALSE)," ") | H12: =IFERROR(VLOOKUP(G12,'Z1 HAB CLASS'!$L$3:$N$9,2,FALSE)," ") | J12: =IFERROR(VLOOKUP(I12,'Z3 CONDITION VALUE'!$A$3:$B$5,2,FALSE)," ") | K12: {=IFERROR(INDEX('Z7 TARGET CREATION'!$C$3:$F$40,MATCH(E12,'Z7 TARGET CREATION'!$B$3:$B$40,0),MATCH(I12,'Z7 TARGET CREATION'!$C$2:$F$2,0)),"")} | L12: =IF(E12="","",VLOOKUP(E12,'Z7 TARGET CREATION'!$G$3:$I$40,3,FALSE)) | M12: =IF(E12="","",VLOOKUP(E12,'Z7 TARGET CREATION'!$G$3:$H$40,2, FALSE)) | N12: =IF(E12="","",IF(K12="Not possible",0,F12*H12*J12*M12)) | W12: =IF(F12="",0,1) -> 0
D13: 7 | G13: =IFERROR(VLOOKUP(E13,'Z1 HAB CLASS'!$D$4:$E$45,2,FALSE)," ") | H13: =IFERROR(VLOOKUP(G13,'Z1 HAB CLASS'!$L$3:$N$9,2,FALSE)," ") | J13: =IFERROR(VLOOKUP(I13,'Z3 CONDITION VALUE'!$A$3:$B$5,2,FALSE)," ") | K13: {=IFERROR(INDEX('Z7 TARGET CREATION'!$C$3:$F$40,MATCH(E13,'Z7 TARGET CREATION'!$B$3:$B$40,0),MATCH(I13,'Z7 TARGET CREATION'!$C$2:$F$2,0)),"")} | L13: =IF(E13="","",VLOOKUP(E13,'Z7 TARGET CREATION'!$G$3:$I$40,3,FALSE)) | M13: =IF(E13="","",VLOOKUP(E13,'Z7 TARGET CREATION'!$G$3:$H$40,2, FALSE)) | N13: =IF(E13="","",IF(K13="Not possible",0,F13*H13*J13*M13)) | W13: =IF(F13="",0,1) -> 0
D14: 8 | G14: =IFERROR(VLOOKUP(E14,'Z1 HAB CLASS'!$D$4:$E$45,2,FALSE)," ") | H14: =IFERROR(VLOOKUP(G14,'Z1 HAB CLASS'!$L$3:$N$9,2,FALSE)," ") | J14: =IFERROR(VLOOKUP(I14,'Z3 CONDITION VALUE'!$A$3:$B$5,2,FALSE)," ") | K14: {=IFERROR(INDEX('Z7 TARGET CREATION'!$C$3:$F$40,MATCH(E14,'Z7 TARGET CREATION'!$B$3:$B$40,0),MATCH(I14,'Z7 TARGET CREATION'!$C$2:$F$2,0)),"")} | L14: =IF(E14="","",VLOOKUP(E14,'Z7 TARGET CREATION'!$G$3:$I$40,3,FALSE)) | M14: =IF(E14="","",VLOOKUP(E14,'Z7 TARGET CREATION'!$G$3:$H$40,2, FALSE)) | N14: =IF(E14="","",IF(K14="Not possible",0,F14*H14*J14*M14)) | W14: =IF(F14="",0,1) -> 0
D15: 9 | G15: =IFERROR(VLOOKUP(E15,'Z1 HAB CLASS'!$D$4:$E$45,2,FALSE)," ") | H15: =IFERROR(VLOOKUP(G15,'Z1 HAB CLASS'!$L$3:$N$9,2,FALSE)," ") | J15: =IFERROR(VLOOKUP(I15,'Z3 CONDITION VALUE'!$A$3:$B$5,2,FALSE)," ") | K15: {=IFERROR(INDEX('Z7 TARGET CREATION'!$C$3:$F$40,MATCH(E15,'Z7 TARGET CREATION'!$B$3:$B$40,0),MATCH(I15,'Z7 TARGET CREATION'!$C$2:$F$2,0)),"")} | L15: =IF(E15="","",VLOOKUP(E15,'Z7 TARGET CREATION'!$G$3:$I$40,3,FALSE)) | M15: =IF(E15="","",VLOOKUP(E15,'Z7 TARGET CREATION'!$G$3:$H$40,2, FALSE)) | N15: =IF(E15="","",IF(K15="Not possible",0,F15*H15*J15*M15)) | W15: =IF(F15="",0,1) -> 0
D16: 10 | G16: =IFERROR(VLOOKUP(E16,'Z1 HAB CLASS'!$D$4:$E$45,2,FALSE)," ") | H16: =IFERROR(VLOOKUP(G16,'Z1 HAB CLASS'!$L$3:$N$9,2,FALSE)," ") | J16: =IFERROR(VLOOKUP(I16,'Z3 CONDITION VALUE'!$A$3:$B$5,2,FALSE)," ") | K16: {=IFERROR(INDEX('Z7 TARGET CREATION'!$C$3:$F$40,MATCH(E16,'Z7 TARGET CREATION'!$B$3:$B$40,0),MATCH(I16,'Z7 TARGET CREATION'!$C$2:$F$2,0)),"")} | L16: =IF(E16="","",VLOOKUP(E16,'Z7 TARGET CREATION'!$G$3:$I$40,3,FALSE)) | M16: =IF(E16="","",VLOOKUP(E16,'Z7 TARGET CREATION'!$G$3:$H$40,2, FALSE)) | N16: =IF(E16="","",IF(K16="Not possible",0,F16*H16*J16*M16)) | W16: =IF(F16="",0,1) -> 0
D17: 11 | G17: =IFERROR(VLOOKUP(E17,'Z1 HAB CLASS'!$D$4:$E$45,2,FALSE)," ") | H17: =IFERROR(VLOOKUP(G17,'Z1 HAB CLASS'!$L$3:$N$9,2,FALSE)," ") | J17: =IFERROR(VLOOKUP(I17,'Z3 CONDITION VALUE'!$A$3:$B$5,2,FALSE)," ") | K17: {=IFERROR(INDEX('Z7 TARGET CREATION'!$C$3:$F$40,MATCH(E17,'Z7 TARGET CREATION'!$B$3:$B$40,0),MATCH(I17,'Z7 TARGET CREATION'!$C$2:$F$2,0)),"")} | L17: =IF(E17="","",VLOOKUP(E17,'Z7 TARGET CREATION'!$G$3:$I$40,3,FALSE)) | M17: =IF(E17="","",VLOOKUP(E17,'Z7 TARGET CREATION'!$G$3:$H$40,2, FALSE)) | N17: =IF(E17="","",IF(K17="Not possible",0,F17*H17*J17*M17)) | W17: =IF(F17="",0,1) -> 0
D18: 12 | G18: =IFERROR(VLOOKUP(E18,'Z1 HAB CLASS'!$D$4:$E$45,2,FALSE)," ") | H18: =IFERROR(VLOOKUP(G18,'Z1 HAB CLASS'!$L$3:$N$9,2,FALSE)," ") | J18: =IFERROR(VLOOKUP(I18,'Z3 CONDITION VALUE'!$A$3:$B$5,2,FALSE)," ") | K18: {=IFERROR(INDEX('Z7 TARGET CREATION'!$C$3:$F$40,MATCH(E18,'Z7 TARGET CREATION'!$B$3:$B$40,0),MATCH(I18,'Z7 TARGET CREATION'!$C$2:$F$2,0)),"")} | L18: =IF(E18="","",VLOOKUP(E18,'Z7 TARGET CREATION'!$G$3:$I$40,3,FALSE)) | M18: =IF(E18="","",VLOOKUP(E18,'Z7 TARGET CREATION'!$G$3:$H$40,2, FALSE)) | N18: =IF(E18="","",IF(K18="Not possible",0,F18*H18*J18*M18)) | W18: =IF(F18="",0,1) -> 0
D19: 13 | G19: =IFERROR(VLOOKUP(E19,'Z1 HAB CLASS'!$D$4:$E$45,2,FALSE)," ") | H19: =IFERROR(VLOOKUP(G19,'Z1 HAB CLASS'!$L$3:$N$9,2,FALSE)," ") | J19: =IFERROR(VLOOKUP(I19,'Z3 CONDITION VALUE'!$A$3:$B$5,2,FALSE)," ") | K19: {=IFERROR(INDEX('Z7 TARGET CREATION'!$C$3:$F$40,MATCH(E19,'Z7 TARGET CREATION'!$B$3:$B$40,0),MATCH(I19,'Z7 TARGET CREATION'!$C$2:$F$2,0)),"")} | L19: =IF(E19="","",VLOOKUP(E19,'Z7 TARGET CREATION'!$G$3:$I$40,3,FALSE)) | M19: =IF(E19="","",VLOOKUP(E19,'Z7 TARGET CREATION'!$G$3:$H$40,2, FALSE)) | N19: =IF(E19="","",IF(K19="Not possible",0,F19*H19*J19*M19)) | W19: =IF(F19="",0,1) -> 0
... D254: 248 | G254: =IFERROR(VLOOKUP(E254,'Z1 HAB CLASS'!$D$4:$E$45,2,FALSE)," ") | H254: =IFERROR(VLOOKUP(G254,'Z1 HAB CLASS'!$L$3:$N$9,2,FALSE)," ") | J254: =IFERROR(VLOOKUP(I254,'Z3 CONDITION VALUE'!$A$3:$B$5,2,FALSE)," ") | K254: {=IFERROR(INDEX('Z7 TARGET CREATION'!$C$3:$F$40,MATCH(E254,'Z7 TARGET CREATION'!$B$3:$B$40,0),MATCH(I254,'Z7 TARGET CREATION'!$C$2:$F$2,0)),"")} | L254: =IF(E254="","",VLOOKUP(E254,'Z7 TARGET CREATION'!$G$3:$I$40,3,FALSE)) | M254: =IF(E254="","",VLOOKUP(E254,'Z7 TARGET CREATION'!$G$3:$H$40,2, FALSE)) | N254: =IF(E254="","",IF(K254="Not possible",0,F254*H254*J254*M254)) | W254: =IF(F254="",0,1) -> 0
E255: Total area | F255: =SUM(F7:F254) -> 4 | M255: Total units | N255: =SUM(N7:N254) -> 6 | W255: =IF(F255="",0,1) -> 1
W256: =IF(F256="",0,1) -> 0

Sheet B1 Baseline - FW
W1: 1
D2: BASELINE | W2: 1
D3: FRESHWATER UNITS | W3: 1
W4: 1
W5: 1
E6: Habitats and Areas | G6: Distinctiveness | I6: Condition | K6: Habitat Trading (compensation requirement) | L6: Ecological Baseline | N6: Lost, Retained and Enhanced Biodiversity Units | T6: Justifications and Comments | W6: 1
D7: Ref | E7: Habitat Type | F7: Area (ha) | G7: Distinctiveness | H7: Score | I7: Condition | J7: Score | L7: Total Freshwater Units | N7: Area Retained (ha) | O7: Area Enhanced (ha) | P7: Baseline Units Retained | Q7: Baseline Units Enhanced | R7: Area lost (ha) | S7: Freshwater Units Lost | W7: 1
